Workbook

Sheet Read me
A1: OTIS COMMERCIAL CLEANING — LEAD TRACKER
A2: Built by Golden Thread Solutions · September 2026 · English-only v2
A4: THE GOAL: LONG-TERM CONTRACTS
A5: Everything in this tracker exists to win recurring contracts. Nothing else is the finish line.
A7: The problem is that you cannot win a contract cold. Almost every business already has a cleaner,
A8: so a contract means replacing someone — and that only happens when they have a reason.
A10: So there are two ways IN, and both of them lead to the same place:
A12: ROUTE 1 — THE ONE-OFF JOB
A13: Strip and wax, post-construction, deep clean, event clean. Work their current cleaner does not do.
A14: Nobody gets replaced. You get inside the building and they watch you work.
A15: → Then you ask about the contract.
A17: ROUTE 2 — THE BACKUP LIST
... A57: Not clean premises. Fewer complaints, and one less problem to manage.

Sheet Compliance pack
A1: COMPLIANCE PACK
A2: Fill in once. Every item here has killed somebody's deal at the last minute.
A4: Item | B4: Why it matters | C4: Status | D4: Owner | E4: Last checked | F4: Notes
A5: — LEGAL —
A6: Commercial General Liability | B6: Norm is $1M per occurrence / $2M aggregate; $2M/$5M for higher-risk sites
A7: Can name client as additional insured | B7: Routinely required before building access is granted
A8: Certificate turnaround time | B8: Buyers verify with the carrier directly. Slow certificates lose jobs
A9: 30-day cancellation notice on policy | B9: Commonly written into contracts
A10: CNESST registered and in good standing | B10: Mandatory for Quebec employers
A11: CNESST attestation de conformite available | B11: Releases the CLIENT from liability for your unpaid contributions. This is a SALES asset
A12: Decree (CPEEP) status confirmed | B12: Client is jointly liable for an underpriced rival's unpaid wages. Same logic — sell it
A13: Crew composition under art. 2.03(2) | B13: Solo or immediate family = outside the decree. One non-family hire moves the floor ~$16/hr to ~$48/hr
A14: Post-reno decree coverage confirmed | B14: Unresolved. Worth ~$7/hr. ONE CALL: CPEEP 514 384-6640
A15: Event-work decree coverage confirmed | B15: Same question, for event and post-event work
A16: NEQ / Quebec business registration | B16: Confirmed active
A18: — COMMERCIAL NORMS —
A19: Named account supervisor | B19: 'No named supervisor' is a known reason deals die after the walkthrough
A20: Inspection schedule and frequency | B20: Must be stated in the proposal, not just done
A21: Complaint process + response time | B21: Buyers are purchasing fewer complaints. Say how you handle them
A22: Staff screening / background checks | B22: You are asking for keys to their building unsupervised
A23: Key handling and after-hours access | B23: The trust gap. Write it down
A24: Scope template: daily vs periodic | B24: Vague scope kills deals
A25: Consumables in or out | B25: Paper, soap. State it or argue about it later
A26: Explicit exclusions list | B26: What costs extra
A27: Pricing model stated | B27: Flat rate vs hourly vs per sq ft
A28: Quote validity period | B28: 30 days is conventional — and a legitimate reason to follow up
A29: Payment terms | B29: Market is net-30, often net-45/60. No deposit as standard policy
A30: Deposit — GC/post-construction only | B30: GCs pay slowly. 20% or progress payments are normal in construction
... A33: References from the 3 existing sites | B33: Ask permission before naming anyone

Sheet Where to look
A1: WHERE TO LOOK
A2: Work top-down. The top of this list produces the best leads for the least effort.
A4: Tier | B4: Source | C4: How to work it | D4: Cost | E4: Effort | F4: Notes / status
A5: 1 | B5: Property & facility managers | C5: Find managers, not buildings. One manager runs many sites — win the relationship and you get the lot. Tenants usually do NOT control the cleaning decision. | D5: Free | E5: High | F5: THE highest-leverage source, and the fastest route to multiple CONTRACTS. Start here.
A6: 1 | B6: Event management companies | C6: Partner for event and post-event cleaning. One relationship = repeat jobs. Evenings/weekends, fits around daytime contracts. | D6: Free | E6: Med | F6: Otis already list Events as a service. Scope: front-of-house, floors, washrooms, waste — NOT kitchens.
A7: 1 | B7: SEAO — Quebec public tenders | C7: seao.gouv.qc.ca — free, no account. Shows OPEN tenders and AWARDED contracts (who won, how much). Schools, CEGEPs, municipalities. | D7: Free | E7: Med | F7: Only place you can see who currently cleans a public body, and when their contract is up.
A8: 1 | B8: Referrals from the 3 existing sites | C8: Ask each site manager who else they know. Incentivise with a discount on their next month. Ask for a REFERRAL, never sell to them. | D8: Free | E8: Low | F8: Highest conversion of anything on this list.
A9: 1 | B9: West Island Chamber of Commerce | C9: ccoim.ca — anglophone-corridor business body, member directory + events. Also SME MTL West Island. | D9: CHECK | E9: Low | F9: Membership cost unconfirmed — verify before spending.
A10: 2 | B10: LinkedIn | C10: Search by JOB TITLE: Facilities Manager, Property Manager, Office Manager. Filter to the corridor. Only platform that finds the decision-maker as a role. | D10: Free | E10: Med | F10: Lead with this if targeting multi-tenant buildings.
A11: 2 | B11: Facebook | C11: (a) Monitor local groups for 'can anyone recommend a commercial cleaner' posts — that is INBOUND, not cold. (b) Marketplace commercial listings = new tenancy. (c) New business pages. | D11: Free | E11: Med | F11: Lead with this if targeting owner-operated single sites.
A12: 2 | B12: → FB groups to build out | C12: Search each corridor name x business/community/shop local/buy-sell. Then by sector. Then follow FB's related-group suggestions. RANK BY: does anyone actually post recommendation requests? | D12: Free | E12: Med | F12: Known so far: West Island Community Montreal; West Island Community; Montreal Business Networking; Montreal Small Business Owners; SHOP LOCAL West Island & Montreal; West Island/Dorval/Lachine Sell-Buy-Advertise. NEEDS A PROPER SWEEP.
A13: 2 | B13: Instagram | C13: Follow GCs, commercial interior designers, architects, commercial realtors. They post finished fit-outs — often pre-occupancy. Identifies the building AND the contractor. | D13: Free | E13: Low | F13: Best single source for the post-construction trigger.
A14: 2 | B14: Registraire des entreprises | C14: New business registrations = new premises = shopping for vendors. | D14: Free | E14: Med | F14: Trigger source.
A15: 2 | B15: Borough permit portals | C15: Renovation and fit-out permits = post-construction work coming. | D15: Free | E15: High | F15: Trigger source. Scattered but doable for one market.
A16: 2 | B16: Commercial real estate listings | C16: New leases and tenancies. | D16: Free | E16: Med | F16: Trigger source.
A17: 2 | B17: AngloINFO Montreal directory | C17: Anglophone-specific business directory. On-target for the chosen market. | D17: Free | E17: Low
A18: 3 | B18: Tenants in buildings already cleaned | C18: Leave cards for other tenants in the 3 current buildings. Word of mouth travels faster inside a building than between them. | D18: Free | E18: Low | F18: Currently not being done. Free.
A19: 3 | B19: General contractors | C19: For post-construction. One operator built a 7-figure business this way and won a 12-person RECURRING contract off one warehouse final-clean. | D19: Free | E19: Med | F19: Pairs with the Instagram monitoring above.
A20: 3 | B20: Adjacent vendors | C20: Food service, landscaping, security firms already serving schools and offices. They know the facilities director and are not competitors. | D20: Free | E20: Low | F20: Referral partnerships.
A21: 3 | B21: Smaller cleaning companies | C21: Overflow partnerships — they pass on work they cannot take. | D21: Free | E21: Low
A22: 3 | B22: Competitor intelligence | C22: Competitor client lists, case studies, and their Google reviews — reviewers routinely name their own business. | D22: Free | E22: Low
A23: 4 | B23: Google Business Profile | C23: Populate Services (currently empty). Turn on messaging. Resume posts. Ask the 3 sites for reviews using COMMERCIAL language. | D23: Free | E23: Low | F23: Visibility, not acquisition. Target ~20 reviews — the janitorial peer set, not 587.
A24: X | B24: Lead-resale services | C24: AVOID. Same lead sold to 3-4 competitors. One operator's client permanently refused a supplier over an aggressive lead rep. | D24: — | E24: — | F24: Do not use.
A25: X | B25: Subcontract-broker models | C25: AVOID. Requires misrepresenting your company structure to clients. | D25: — | E25: — | F25: Do not use.

Sheet Leads
A1: BLUE = the skill fills this | E1: AMBER = YOU fill this by hand | I1: GREY = automatic, never type here
A2: A · WHO | H2: B · CURRENT CLEANER | O2: C · WHY NOW | U2: D · CONTACT | AA2: E · CASL EVIDENCE | AC2: F · PIPELINE | AN2: G · CASH | AQ2: H · PATH TO CONTRACT
A3: Business name | B3: Sector | C3: Neighbourhood | D3: Language | E3: Approx sq ft | F3: Public or private | G3: Property manager (if any) | H3: Has a cleaner? | I3: Who | J3: How we know | K3: Contract value (public) | L3: Award date | M3: Est. renewal window | N3: SEAO ref | O3: Trigger | P3: Trigger live until | Q3: Hard floors? | R3: Best-fit offer | S3: Score | T3: Priority | U3: Contact name | V3: Role | W3: Phone | X3: Email | Y3: Best approach | Z3: Referred by | AA3: Source URL | AB3: Date collected | AC3: Date approached | AD3: Status | AE3: Walkthrough booked | AF3: Walkthrough done | AG3: Proposal sent | AH3: Days to proposal | AI3: Quote value $ | AJ3: Payment terms | AK3: Compliance pack sent? | AL3: Job date | AM3: Follow-up date | AN3: Invoiced date | AO3: Paid date | AP3: Amount paid $ | AQ3: On backup list? | AR3: Contract stage | AS3: Contract value $/mo | AT3: Notes
A4: Cromwell Management | B4: Property manager | C4: Kirkland | D4: EN | E4: 25000 | F4: Private | G4: — | H4: Unknown | J4: Not yet known | O4: Pre-winter floors | P4: 46327 | Q4: Unknown | R4: One-off - Strip & wax | S4: =IF($A4="","",IF(LEFT($B4,2)="DQ",0,(IF($Q4="Yes",1,0)+IF(AND($O4<>"",$O4<>"None known",OR($P4="",$P4>=TODAY())),1,0)+IF(AND($B4<>"",LEFT($B4,2)<>"DQ"),1,0)+IF(AND($C4<>"",$C4<>"Outside corridor"),1,0)+IF(AND($W4<>"",$U4<>""),1,0)+IF(AND(ISNUMBER($E4),$E4>=3000,$E4<=15000),1,0)))) -> 4 | T4: =IF($A4="","",IF(LEFT($B4,2)="DQ","DQ - do not work",IF(AND($P4<>"",$P4<TODAY()),"STALE - refresh",IF($S4>=5,"A - go now",IF($S4>=3,"B - worth it","C - later"))))) -> B - worth it | U4: Michael Doroshenko | V4: Director of Commercial Leasing | W4: 514-824-2278 | Y4: Call | AA4: https://cromwellmgt.ca/en/contact/ | AB4: 46281 | AD4: Not started | AH4: =IF(OR($AF4="",$AG4=""),"",$AG4-$AF4) | AM4: =IF($AG4="","",$AG4+30) | AR4: Not yet raised | AT4: CALL ONLY - a placeholder email was removed on 16 Sept 2026. No published address verified, so there is no CASL basis. Michael Doroshenko, Director of Commercial Leasing, is a named contact found on a commercial property listing - phone him.
A5: Groupe Shapiro | B5: Property manager | C5: Pointe-Claire | D5: Bilingual | F5: Private | O5: New tenancy / move | P5: 46327 | Q5: Unknown | R5: One-off - Strip & wax | S5: =IF($A5="","",IF(LEFT($B5,2)="DQ",0,(IF($Q5="Yes",1,0)+IF(AND($O5<>"",$O5<>"None known",OR($P5="",$P5>=TODAY())),1,0)+IF(AND($B5<>"",LEFT($B5,2)<>"DQ"),1,0)+IF(AND($C5<>"",$C5<>"Outside corridor"),1,0)+IF(AND($W5<>"",$U5<>""),1,0)+IF(AND(ISNUMBER($E5),$E5>=3000,$E5<=15000),1,0)))) -> 4 | T5: =IF($A5="","",IF(LEFT($B5,2)="DQ","DQ - do not work",IF(AND($P5<>"",$P5<TODAY()),"STALE - refresh",IF($S5>=5,"A - go now",IF($S5>=3,"B - worth it","C - later"))))) -> B - worth it | U5: Matthew Krantzberg | V5: Leasing - 225 Hymus | W5: 514-833-6208 | Y5: Call | AA5: https://www.loopnet.ca/Listing/225-Boul-Hymus-Pointe-claire-QC/28602128/ | AB5: 46281 | AD5: Not started | AH5: =IF(OR($AF5="",$AG5=""),"",$AG5-$AF5) | AM5: =IF($AG5="","",$AG5+30) | AR5: Not yet raised | AT5: TIER 1. Manages 225 Boul Hymus, Pointe-Claire - offices 100-2,000 sq ft, newly renovated, COMMON WASHROOMS (shared areas = the cleaning contract). Multi-tenant, so new tenants arrive constantly. Other contacts: Steven Glazer 514-933-5112 x262, Gregory Depatie 514-951-8587. $30/sq ft/yr asking.
A6: TRAMS Property Management | B6: Property manager | C6: Other - in corridor | D6: EN | F6: Private | O6: Pre-winter floors | P6: 46327 | Q6: Unknown | R6: One-off - Strip & wax | S6: =IF($A6="","",IF(LEFT($B6,2)="DQ",0,(IF($Q6="Yes",1,0)+IF(AND($O6<>"",$O6<>"None known",OR($P6="",$P6>=TODAY())),1,0)+IF(AND($B6<>"",LEFT($B6,2)<>"DQ"),1,0)+IF(AND($C6<>"",$C6<>"Outside corridor"),1,0)+IF(AND($W6<>"",$U6<>""),1,0)+IF(AND(ISNUMBER($E6),$E6>=3000,$E6<=15000),1,0)))) -> 3 | T6: =IF($A6="","",IF(LEFT($B6,2)="DQ","DQ - do not work",IF(AND($P6<>"",$P6<TODAY()),"STALE - refresh",IF($S6>=5,"A - go now",IF($S6>=3,"B - worth it","C - later"))))) -> B - worth it | V6: Reception - ask for property manager | W6: 514-341-8600 | X6: info@tramsmgmt.com | Y6: Call | AA6: https://tramsmgmt.com/ | AB6: 46281 | AD6: Not started | AH6: =IF(OR($AF6="",$AG6=""),"",$AG6-$AF6) | AM6: =IF($AG6="","",$AG6+30) | AR6: Not yet raised | AT6: TIER 1. COMMERCIAL properties in Dollard-des-Ormeaux, Kirkland and Anjou - all corridor. Office 5151 de la Savane. No named contact published - get one on the call.
A7: VS Property Management / VS Gestion Immobiliere | B7: Property manager | C7: Lachine | D7: Bilingual | E7: 24746 | F7: Private | O7: Pre-winter floors | P7: 46327 | Q7: Unknown | R7: One-off - Strip & wax | S7: =IF($A7="","",IF(LEFT($B7,2)="DQ",0,(IF($Q7="Yes",1,0)+IF(AND($O7<>"",$O7<>"None known",OR($P7="",$P7>=TODAY())),1,0)+IF(AND($B7<>"",LEFT($B7,2)<>"DQ"),1,0)+IF(AND($C7<>"",$C7<>"Outside corridor"),1,0)+IF(AND($W7<>"",$U7<>""),1,0)+IF(AND(ISNUMBER($E7),$E7>=3000,$E7<=15000),1,0)))) -> 3 | T7: =IF($A7="","",IF(LEFT($B7,2)="DQ","DQ - do not work",IF(AND($P7<>"",$P7<TODAY()),"STALE - refresh",IF($S7>=5,"A - go now",IF($S7>=3,"B - worth it","C - later"))))) -> B - worth it | V7: Reception - ask for property manager | W7: 438-265-1855 | X7: info@vsgestionimmo.com | Y7: Call | AA7: https://www.vsgestionimmo.com/ | AB7: 46281 | AD7: Not started | AH7: =IF(OR($AF7="",$AG7=""),"",$AG7-$AF7) | AM7: =IF($AG7="","",$AG7+30) | AR7: Not yet raised | AT7: TIER 1. Commercial/retail/industrial. Corridor property: 9960-9970 Cote-de-Liesse, Lachine (24,746 sq ft). Head office is Brossard - lead with the Lachine building, not the company.
A8: World Gym Dollard-des-Ormeaux | B8: Gym / Studio | C8: Dollard-des-Ormeaux | D8: Bilingual | E8: 42000 | F8: Private | O8: Pre-winter floors | P8: 46327 | Q8: Yes | R8: One-off - Strip & wax | S8: =IF($A8="","",IF(LEFT($B8,2)="DQ",0,(IF($Q8="Yes",1,0)+IF(AND($O8<>"",$O8<>"None known",OR($P8="",$P8>=TODAY())),1,0)+IF(AND($B8<>"",LEFT($B8,2)<>"DQ"),1,0)+IF(AND($C8<>"",$C8<>"Outside corridor"),1,0)+IF(AND($W8<>"",$U8<>""),1,0)+IF(AND(ISNUMBER($E8),$E8>=3000,$E8<=15000),1,0)))) -> 4 | T8: =IF($A8="","",IF(LEFT($B8,2)="DQ","DQ - do not work",IF(AND($P8<>"",$P8<TODAY()),"STALE - refresh",IF($S8>=5,"A - go now",IF($S8>=3,"B - worth it","C - later"))))) -> B - worth it | V8: Reception - ask for club manager | W8: 438-600-2100 | Y8: Walk-in | AA8: https://wgq.ca/en/world-gym-dollard-des-ormeaux/ | AB8: 46281 | AD8: Not started | AH8: =IF(OR($AF8="",$AG8=""),"",$AG8-$AF8) | AM8: =IF($AG8="","",$AG8+30) | AR8: Not yet raised | AT8: 42,000 SQ FT - largest in this batch. 3237 Des Sources Blvd. Open 24h Tue-Thu, so floor work needs planning - but high traffic plus winter salt makes this the strongest floor-care case here. No email published: CALL OR WALK IN ONLY.
A9: GYM Fit Forme Pointe-Claire | B9: Gym / Studio | C9: Pointe-Claire | D9: Bilingual | F9: Private | O9: Pre-winter floors | P9: 46327 | Q9: Yes | R9: One-off - Strip & wax | S9: =IF($A9="","",IF(LEFT($B9,2)="DQ",0,(IF($Q9="Yes",1,0)+IF(AND($O9<>"",$O9<>"None known",OR($P9="",$P9>=TODAY())),1,0)+IF(AND($B9<>"",LEFT($B9,2)<>"DQ"),1,0)+IF(AND($C9<>"",$C9<>"Outside corridor"),1,0)+IF(AND($W9<>"",$U9<>""),1,0)+IF(AND(ISNUMBER($E9),$E9>=3000,$E9<=15000),1,0)))) -> 4 | T9: =IF($A9="","",IF(LEFT($B9,2)="DQ","DQ - do not work",IF(AND($P9<>"",$P9<TODAY()),"STALE - refresh",IF($S9>=5,"A - go now",IF($S9>=3,"B - worth it","C - later"))))) -> B - worth it | V9: Reception - ask for manager | W9: 514-643-1888 | Y9: Walk-in | AA9: https://gymfitforme.com/en/west-island/ | AB9: 46281 | AD9: Not started | AH9: =IF(OR($AF9="",$AG9=""),"",$AG9-$AF9) | AM9: =IF($AG9="","",$AG9+30) | AR9: Not yet raised | AT9: 2375 Trans-Canada Hwy, Pointe-Claire. ONE OF FOUR BRANCHES - a win here could become four sites. Showers and saunas add wet-area work. 24h for premium members. No email published: CALL OR WALK IN ONLY.
A10: Energie EnCorps | B10: Gym / Studio | C10: Pointe-Claire | D10: Bilingual | F10: Private | O10: Pre-winter floors | P10: 46327 | Q10: Yes | R10: One-off - Deep clean | S10: =IF($A10="","",IF(LEFT($B10,2)="DQ",0,(IF($Q10="Yes",1,0)+IF(AND($O10<>"",$O10<>"None known",OR($P10="",$P10>=TODAY())),1,0)+IF(AND($B10<>"",LEFT($B10,2)<>"DQ"),1,0)+IF(AND($C10<>"",$C10<>"Outside corridor"),1,0)+IF(AND($W10<>"",$U10<>""),1,0)+IF(AND(ISNUMBER($E10),$E10>=3000,$E10<=15000),1,0)))) -> 4 | T10: =IF($A10="","",IF(LEFT($B10,2)="DQ","DQ - do not work",IF(AND($P10<>"",$P10<TODAY()),"STALE - refresh",IF($S10>=5,"A - go now",IF($S10>=3,"B - worth it","C - later"))))) -> B - worth it | V10: Reception - ask for owner | W10: 514-505-9642 | Y10: Walk-in | AA10: https://energieencorps.com/contact/ | AB10: 46281 | AD10: Not started | AH10: =IF(OR($AF10="",$AG10=""),"",$AG10-$AF10) | AM10: =IF($AG10="","",$AG10+30) | AR10: Not yet raised | AT10: 18 Place de la Triade #230, Pointe-Claire. Yoga, fitness and holistic health - 35+ classes a week plus massage, osteopathy, reiki. Treatment rooms mean hygiene matters more than in a normal gym. No email published: CALL OR WALK IN ONLY.
A11: The Learning Tree Daycare | B11: Daycare / CPE | C11: Dollard-des-Ormeaux | D11: EN | F11: Private | O11: Pre-winter floors | P11: 46327 | Q11: Unknown | R11: One-off - Deep clean | S11: =IF($A11="","",IF(LEFT($B11,2)="DQ",0,(IF($Q11="Yes",1,0)+IF(AND($O11<>"",$O11<>"None known",OR($P11="",$P11>=TODAY())),1,0)+IF(AND($B11<>"",LEFT($B11,2)<>"DQ"),1,0)+IF(AND($C11<>"",$C11<>"Outside corridor"),1,0)+IF(AND($W11<>"",$U11<>""),1,0)+IF(AND(ISNUMBER($E11),$E11>=3000,$E11<=15000),1,0)))) -> 3 | T11: =IF($A11="","",IF(LEFT($B11,2)="DQ","DQ - do not work",IF(AND($P11<>"",$P11<TODAY()),"STALE - refresh",IF($S11>=5,"A - go now",IF($S11>=3,"B - worth it","C - later"))))) -> B - worth it | V11: Reception - ask for director | W11: 514-683-8426 | Y11: Call | AA11: https://thelearningtree.ca/contact-us/ | AB11: 46281 | AD11: Not started | AH11: =IF(OR($AF11="",$AG11=""),"",$AG11-$AF11) | AM11: =IF($AG11="","",$AG11+30) | AR11: Not yet raised | AT11: 16 Rue de Seville, DDO. ANGLOPHONE daycare serving Kirkland, Pierrefonds, Pointe-Claire, DDO. Regulation angle applies: equipment must be disinfected outside childrens presence - which means evenings, which means a contract. No email published: CALL ONLY.
A12: Garderie Bebe et Cie | B12: Daycare / CPE | C12: Other - in corridor | D12: Bilingual | F12: Private | O12: Pre-winter floors | P12: 46327 | Q12: Unknown | R12: One-off - Deep clean | S12: =IF($A12="","",IF(LEFT($B12,2)="DQ",0,(IF($Q12="Yes",1,0)+IF(AND($O12<>"",$O12<>"None known",OR($P12="",$P12>=TODAY())),1,0)+IF(AND($B12<>"",LEFT($B12,2)<>"DQ"),1,0)+IF(AND($C12<>"",$C12<>"Outside corridor"),1,0)+IF(AND($W12<>"",$U12<>""),1,0)+IF(AND(ISNUMBER($E12),$E12>=3000,$E12<=15000),1,0)))) -> 3 | T12: =IF($A12="","",IF(LEFT($B12,2)="DQ","DQ - do not work",IF(AND($P12<>"",$P12<TODAY()),"STALE - refresh",IF($S12>=5,"A - go now",IF($S12>=3,"B - worth it","C - later"))))) -> B - worth it | V12: Reception - ask for director | W12: 514-583-8309 | X12: info@bebeetcie.com | Y12: Call | AA12: http://bebeetcie.com/ | AB12: 46281 | AD12: Not started | AH12: =IF(OR($AF12="",$AG12=""),"",$AG12-$AF12) | AM12: =IF($AG12="","",$AG12+30) | AR12: Not yet raised | AT12: 4830 Boul St-Jean, Pierrefonds. Ages 3 months to 5 years. Closed weekends = clean access Sat/Sun. Same regulation angle as any daycare: disinfection outside childrens presence.
A13: Clinique Dentaire Pointe-Claire | B13: Medical clinic | C13: Pointe-Claire | D13: Bilingual | F13: Private | O13: New tenancy / move | P13: 46327 | Q13: Yes | R13: One-off - Strip & wax | S13: =IF($A13="","",IF(LEFT($B13,2)="DQ",0,(IF($Q13="Yes",1,0)+IF(AND($O13<>"",$O13<>"None known",OR($P13="",$P13>=TODAY())),1,0)+IF(AND($B13<>"",LEFT($B13,2)<>"DQ"),1,0)+IF(AND($C13<>"",$C13<>"Outside corridor"),1,0)+IF(AND($W13<>"",$U13<>""),1,0)+IF(AND(ISNUMBER($E13),$E13>=3000,$E13<=15000),1,0)))) -> 5 | T13: =IF($A13="","",IF(LEFT($B13,2)="DQ","DQ - do not work",IF(AND($P13<>"",$P13<TODAY()),"STALE - refresh",IF($S13>=5,"A - go now",IF($S13>=3,"B - worth it","C - later"))))) -> A - go now | U13: Catalina Zambrano | V13: Privacy Officer - route to office manager | W13: 514-697-7391 | X13: info@cliniquedentairepointeclaire.com | Y13: Call | AA13: https://cliniquedentairepointeclaire.com/about-us/ | AB13: 46281 | AD13: Not started | AH13: =IF(OR($AF13="",$AG13=""),"",$AG13-$AF13) | AM13: =IF($AG13="","",$AG13+30) | AR13: Not yet raised | AT13: 1 Ave Holiday #250, Pointe-Claire. TWO TRIGGERS: recently relocated to Holiday Ave (new premises) AND pre-winter floors. 30+ yrs in the West Island. Multiple operatories. Closed weekends = clean access. Hard floors inferred from clinical norms; confirm at walkthrough.
A14: Centre Dentaire Lakeshore | B14: Medical clinic | C14: Kirkland | D14: EN | F14: Private | O14: Pre-winter floors | P14: 46327 | Q14: Yes | R14: One-off - Strip & wax | S14: =IF($A14="","",IF(LEFT($B14,2)="DQ",0,(IF($Q14="Yes",1,0)+IF(AND($O14<>"",$O14<>"None known",OR($P14="",$P14>=TODAY())),1,0)+IF(AND($B14<>"",LEFT($B14,2)<>"DQ"),1,0)+IF(AND($C14<>"",$C14<>"Outside corridor"),1,0)+IF(AND($W14<>"",$U14<>""),1,0)+IF(AND(ISNUMBER($E14),$E14>=3000,$E14<=15000),1,0)))) -> 5 | T14: =IF($A14="","",IF(LEFT($B14,2)="DQ","DQ - do not work",IF(AND($P14<>"",$P14<TODAY()),"STALE - refresh",IF($S14>=5,"A - go now",IF($S14>=3,"B - worth it","C - later"))))) -> A - go now | U14: Dr Sochea Da Lung-Tor | V14: Principal dentist | W14: 514-694-5716 | Y14: Call | AA14: https://centredentairelakeshore.com/get-in-touch/ | AB14: 46281 | AD14: Not started | AH14: =IF(OR($AF14="",$AG14=""),"",$AG14-$AF14) | AM14: =IF($AG14="","",$AG14+30) | AR14: Not yet raised | AT14: 22 Canvin St, Kirkland. 3 dentists, 8 staff. Behind Lakeshore General Hospital. Second dentist: Dr Duc-Minh Lam-Do. NO EMAIL PUBLISHED - CALL ONLY, no CASL basis to email. Hard floors inferred from clinical norms.
A15: Beaconsfield Dentistry | B15: Medical clinic | C15: Kirkland | D15: EN | F15: Private | O15: Pre-winter floors | P15: 46327 | Q15: Yes | R15: One-off - Strip & wax | S15: =IF($A15="","",IF(LEFT($B15,2)="DQ",0,(IF($Q15="Yes",1,0)+IF(AND($O15<>"",$O15<>"None known",OR($P15="",$P15>=TODAY())),1,0)+IF(AND($B15<>"",LEFT($B15,2)<>"DQ"),1,0)+IF(AND($C15<>"",$C15<>"Outside corridor"),1,0)+IF(AND($W15<>"",$U15<>""),1,0)+IF(AND(ISNUMBER($E15),$E15>=3000,$E15<=15000),1,0)))) -> 5 | T15: =IF($A15="","",IF(LEFT($B15,2)="DQ","DQ - do not work",IF(AND($P15<>"",$P15<TODAY()),"STALE - refresh",IF($S15>=5,"A - go now",IF($S15>=3,"B - worth it","C - later"))))) -> A - go now | U15: Dr Mark Reich | V15: Principal dentist | W15: 514-697-7107 | X15: contact@beaconsfielddentistry.com | Y15: Call | AA15: https://beaconsfielddentistry.com/contact.php | AB15: 46281 | AD15: Not started | AH15: =IF(OR($AF15="",$AG15=""),"",$AG15-$AF15) | AM15: =IF($AG15="","",$AG15+30) | AR15: Not yet raised | AT15: 2969 Saint Charles Blvd, Kirkland. 50+ yrs in the West Island. Second dentist: Dr Paul Deep. Closes 3pm Fridays - good weekend access. Hard floors inferred from clinical norms.
A16: Beaconsfield Medical Clinic | B16: Medical clinic | C16: Beaconsfield | D16: EN | F16: Private | O16: Pre-winter floors | P16: 46327 | Q16: Yes | R16: One-off - Strip & wax | S16: =IF($A16="","",IF(LEFT($B16,2)="DQ",0,(IF($Q16="Yes",1,0)+IF(AND($O16<>"",$O16<>"None known",OR($P16="",$P16>=TODAY())),1,0)+IF(AND($B16<>"",LEFT($B16,2)<>"DQ"),1,0)+IF(AND($C16<>"",$C16<>"Outside corridor"),1,0)+IF(AND($W16<>"",$U16<>""),1,0)+IF(AND(ISNUMBER($E16),$E16>=3000,$E16<=15000),1,0)))) -> 4 | T16: =IF($A16="","",IF(LEFT($B16,2)="DQ","DQ - do not work",IF(AND($P16<>"",$P16<TODAY()),"STALE - refresh",IF($S16>=5,"A - go now",IF($S16>=3,"B - worth it","C - later"))))) -> B - worth it | V16: Reception - ask for clinic manager | W16: 514-375-5342 | Y16: Call | AA16: https://www.cmbeaconsfield.com/en/contact-us | AB16: 46281 | AD16: Not started | AH16: =IF(OR($AF16="",$AG16=""),"",$AG16-$AF16) | AM16: =IF($AG16="","",$AG16+30) | AR16: Not yet raised | AT16: Doctors, nurse practitioners AND an on-site pharmacy - bigger footprint than a dental practice. Serves Beaconsfield, Pierrefonds, Pointe-Claire, Kirkland. NO EMAIL PUBLISHED - CALL ONLY. Get the clinic managers name on the call.
A17: Placements Sergakis Inc. (181 Hymus + portfolio) | B17: Office | C17: Pointe-Claire | D17: EN | F17: Private | G17: Self-managed | O17: Pre-winter floors | P17: 46327 | Q17: Yes | R17: One-off - Strip & wax | S17: =IF($A17="","",IF(LEFT($B17,2)="DQ",0,(IF($Q17="Yes",1,0)+IF(AND($O17<>"",$O17<>"None known",OR($P17="",$P17>=TODAY())),1,0)+IF(AND($B17<>"",LEFT($B17,2)<>"DQ"),1,0)+IF(AND($C17<>"",$C17<>"Outside corridor"),1,0)+IF(AND($W17<>"",$U17<>""),1,0)+IF(AND(ISNUMBER($E17),$E17>=3000,$E17<=15000),1,0)))) -> 5 | T17: =IF($A17="","",IF(LEFT($B17,2)="DQ","DQ - do not work",IF(AND($P17<>"",$P17<TODAY()),"STALE - refresh",IF($S17>=5,"A - go now",IF($S17>=3,"B - worth it","C - later"))))) -> A - go now | U17: Sylvie Filion | V17: Supervisor, Repairs and Maintenance | W17: 514-937-6137 ext 225 | X17: Sylvie.fillion@sergakis.com | Y17: Email | AA17: https://en.sergakis.com/contactez-nous | AB17: 46281 | AH17: =IF(OR($AF17="",$AG17=""),"",$AG17-$AF17) | AM17: =IF($AG17="","",$AG17+30) | AT17: BEST OF BATCH. Multi-building commercial + residential landlord, head office LaSalle. Publishes a named maintenance supervisor with direct email on its own contact page - that is the cleaning buyer, published, CASL-clean. Second contact: Mark Bedard, Commercial Real Estate Director, mbedard@sergakis.com, 514-803-0011. 181 Hymus Pointe-Claire office listed 1,660-13,260 sq ft. One relationship covers a portfolio.
A18: Michael White Realties Inc. (271 Labrosse) | B18: Office | C18: Pointe-Claire | D18: EN | F18: Private | G18: Michael White Realties | O18: Pre-winter floors | P18: 46327 | Q18: Yes | R18: One-off - Strip & wax | S18: =IF($A18="","",IF(LEFT($B18,2)="DQ",0,(IF($Q18="Yes",1,0)+IF(AND($O18<>"",$O18<>"None known",OR($P18="",$P18>=TODAY())),1,0)+IF(AND($B18<>"",LEFT($B18,2)<>"DQ"),1,0)+IF(AND($C18<>"",$C18<>"Outside corridor"),1,0)+IF(AND($W18<>"",$U18<>""),1,0)+IF(AND(ISNUMBER($E18),$E18>=3000,$E18<=15000),1,0)))) -> 4 | T18: =IF($A18="","",IF(LEFT($B18,2)="DQ","DQ - do not work",IF(AND($P18<>"",$P18<TODAY()),"STALE - refresh",IF($S18>=5,"A - go now",IF($S18>=3,"B - worth it","C - later"))))) -> B - worth it | W18: 514-488-5111 | X18: mwr@whiteinc.ca | Y18: Email | AA18: https://www.mwr.ca/contact-us/ | AB18: 46281 | AH18: =IF(OR($AF18="",$AG18=""),"",$AG18-$AF18) | AM18: =IF($AG18="","",$AG18+30) | AT18: Commercial/industrial brokerage and manager, office at 6800 Cote-de-Liesse Saint-Laurent. Manages 271 Av Labrosse Pointe-Claire, 1,000-10,000 sq ft office. General published email only - ask for whoever handles building services.
A19: Groupe Petra (1 Holiday Ave) | B19: Office | C19: Pointe-Claire | D19: EN | E19: 19508 | F19: Private | G19: Groupe Petra Ltd | O19: Pre-winter floors | P19: 46327 | Q19: Yes | R19: One-off - Strip & wax | S19: =IF($A19="","",IF(LEFT($B19,2)="DQ",0,(IF($Q19="Yes",1,0)+IF(AND($O19<>"",$O19<>"None known",OR($P19="",$P19>=TODAY())),1,0)+IF(AND($B19<>"",LEFT($B19,2)<>"DQ"),1,0)+IF(AND($C19<>"",$C19<>"Outside corridor"),1,0)+IF(AND($W19<>"",$U19<>""),1,0)+IF(AND(ISNUMBER($E19),$E19>=3000,$E19<=15000),1,0)))) -> 4 | T19: =IF($A19="","",IF(LEFT($B19,2)="DQ","DQ - do not work",IF(AND($P19<>"",$P19<TODAY()),"STALE - refresh",IF($S19>=5,"A - go now",IF($S19>=3,"B - worth it","C - later"))))) -> B - worth it | W19: 514-321-7515 | X19: info@groupepetra.com | Y19: Email | AA19: https://groupepetra.com/ | AB19: 46281 | AH19: =IF(OR($AF19="",$AG19=""),"",$AG19-$AF19) | AM19: =IF($AG19="","",$AG19+30) | AT19: Manages 1 Av Holiday Pointe-Claire, 994-19,508 sq ft office building. Head office 8000 Langelier, Saint-Leonard. Large portfolio incl. 1000 de la Gauchetiere. General published email only.
A20: Epic Quebec Inc. (6000 Trans-Canada, Dorval) | B20: Office | C20: Dorval | D20: EN | E20: 218338 | F20: Private | G20: Epic Quebec / Epic Investment Services | O20: Pre-winter floors | P20: 46327 | Q20: Yes | R20: One-off - Strip & wax | S20: =IF($A20="","",IF(LEFT($B20,2)="DQ",0,(IF($Q20="Yes",1,0)+IF(AND($O20<>"",$O20<>"None known",OR($P20="",$P20>=TODAY())),1,0)+IF(AND($B20<>"",LEFT($B20,2)<>"DQ"),1,0)+IF(AND($C20<>"",$C20<>"Outside corridor"),1,0)+IF(AND($W20<>"",$U20<>""),1,0)+IF(AND(ISNUMBER($E20),$E20>=3000,$E20<=15000),1,0)))) -> 5 | T20: =IF($A20="","",IF(LEFT($B20,2)="DQ","DQ - do not work",IF(AND($P20<>"",$P20<TODAY()),"STALE - refresh",IF($S20>=5,"A - go now",IF($S20>=3,"B - worth it","C - later"))))) -> A - go now | U20: Sabrina Grassi | V20: Leasing contact | W20: 438-812-7878 | X20: ldragu@epicquebec.com | Y20: Email | AA20: https://ia.ca/business/office-space/6000-trans-canada-highway | AB20: 46281 | AH20: =IF(OR($AF20="",$AG20=""),"",$AG20-$AF20) | AM20: =IF($AG20="","",$AG20+30) | AT20: Manages 6000 Trans-Canada for iA Financial Group. Building is 218,338 sq ft, expanded 2010 and 2014 - industrial/office mix with 18 docks, so likely ABOVE Otis capacity for a full contract; work it for one-off floor care and the backup list, not a recurring bid. Published email is on the landlord's leasing page.
A21: BGI - 6600 Trans-Canada, Pointe-Claire | B21: Office | C21: Pointe-Claire | D21: EN | E21: 85454 | F21: Private | G21: BGI | O21: Pre-winter floors | P21: 46327 | Q21: Yes | R21: One-off - Strip & wax | S21: =IF($A21="","",IF(LEFT($B21,2)="DQ",0,(IF($Q21="Yes",1,0)+IF(AND($O21<>"",$O21<>"None known",OR($P21="",$P21>=TODAY())),1,0)+IF(AND($B21<>"",LEFT($B21,2)<>"DQ"),1,0)+IF(AND($C21<>"",$C21<>"Outside corridor"),1,0)+IF(AND($W21<>"",$U21<>""),1,0)+IF(AND(ISNUMBER($E21),$E21>=3000,$E21<=15000),1,0)))) -> 4 | T21: =IF($A21="","",IF(LEFT($B21,2)="DQ","DQ - do not work",IF(AND($P21<>"",$P21<TODAY()),"STALE - refresh",IF($S21>=5,"A - go now",IF($S21>=3,"B - worth it","C - later"))))) -> B - worth it | Y21: Walk-in | AA21: https://www.loopnet.ca/Listing/6600-Rte-Transcanadienne-Pointe-claire-QC/26089956/ | AB21: 46281 | AH21: =IF(OR($AF21="",$AG21=""),"",$AG21-$AF21) | AM21: =IF($AG21="","",$AG21+30) | AT21: CALL ONLY / WALK-IN - no published email found. 85,454 sq ft multi-tenant office, built 1975, listing states 'Property Manager on Site'. Older building with a new interior restaurant fit-out = live renovation signal. On-site manager means a walk-in is realistic. Suites 450-6,582 sq ft.
A22: Plaza Pointe Claire Inc. (245-325 St-Jean) | B22: Office | C22: Pointe-Claire | D22: EN | E22: 16807 | F22: Private | G22: Plaza Pointe Claire Inc. | O22: Pre-winter floors | P22: 46327 | Q22: Yes | R22: One-off - Strip & wax | S22: =IF($A22="","",IF(LEFT($B22,2)="DQ",0,(IF($Q22="Yes",1,0)+IF(AND($O22<>"",$O22<>"None known",OR($P22="",$P22>=TODAY())),1,0)+IF(AND($B22<>"",LEFT($B22,2)<>"DQ"),1,0)+IF(AND($C22<>"",$C22<>"Outside corridor"),1,0)+IF(AND($W22<>"",$U22<>""),1,0)+IF(AND(ISNUMBER($E22),$E22>=3000,$E22<=15000),1,0)))) -> 4 | T22: =IF($A22="","",IF(LEFT($B22,2)="DQ","DQ - do not work",IF(AND($P22<>"",$P22<TODAY()),"STALE - refresh",IF($S22>=5,"A - go now",IF($S22>=3,"B - worth it","C - later"))))) -> B - worth it | Y22: Call | AA22: https://www.loopnet.ca/search/office-space/pointe-claire-qc--canada/for-lease/ | AB22: 46281 | AH22: =IF(OR($AF22="",$AG22=""),"",$AG22-$AF22) | AM22: =IF($AG22="","",$AG22+30) | AT22: CALL ONLY - no published email found. Office space 657-16,807 sq ft across 245-325 Boul Saint-Jean. Owner-managed. Needs a name before it is workable.
A23: Kells Academy (3 campuses) | B23: School | C23: NDG | D23: EN | F23: Private | O23: Pre-winter floors | P23: 46327 | Q23: Yes | R23: One-off - Strip & wax | S23: =IF($A23="","",IF(LEFT($B23,2)="DQ",0,(IF($Q23="Yes",1,0)+IF(AND($O23<>"",$O23<>"None known",OR($P23="",$P23>=TODAY())),1,0)+IF(AND($B23<>"",LEFT($B23,2)<>"DQ"),1,0)+IF(AND($C23<>"",$C23<>"Outside corridor"),1,0)+IF(AND($W23<>"",$U23<>""),1,0)+IF(AND(ISNUMBER($E23),$E23>=3000,$E23<=15000),1,0)))) -> 4 | T23: =IF($A23="","",IF(LEFT($B23,2)="DQ","DQ - do not work",IF(AND($P23<>"",$P23<TODAY()),"STALE - refresh",IF($S23>=5,"A - go now",IF($S23>=3,"B - worth it","C - later"))))) -> B - worth it | W23: 514-487-2345 | X23: kadmin@kells.ca | Y23: Email | AA23: https://kells.ca/index.php?Itemid=203 | AB23: 46281 | AH23: =IF(OR($AF23="",$AG23=""),"",$AG23-$AF23) | AM23: =IF($AG23="","",$AG23+30) | AT23: STRONGEST SCHOOL LEAD. Three campuses, all H4B - the same postcode district as Otis at 2447 Madison Ave. Elementary 2290 Cavendish; High School 6865 De Maisonneuve W; Grade 12 6645 De Maisonneuve W. ~300 students total so each site is mid-size, inside capacity. Three buildings under one administration = contract-shaped from the first conversation. Published general admin email.
A24: Hebrew Foundation School | B24: School | C24: Dollard-des-Ormeaux | D24: EN | F24: Private | O24: Pre-winter floors | P24: 46327 | Q24: Yes | R24: One-off - Strip & wax | S24: =IF($A24="","",IF(LEFT($B24,2)="DQ",0,(IF($Q24="Yes",1,0)+IF(AND($O24<>"",$O24<>"None known",OR($P24="",$P24>=TODAY())),1,0)+IF(AND($B24<>"",LEFT($B24,2)<>"DQ"),1,0)+IF(AND($C24<>"",$C24<>"Outside corridor"),1,0)+IF(AND($W24<>"",$U24<>""),1,0)+IF(AND(ISNUMBER($E24),$E24>=3000,$E24<=15000),1,0)))) -> 4 | T24: =IF($A24="","",IF(LEFT($B24,2)="DQ","DQ - do not work",IF(AND($P24<>"",$P24<TODAY()),"STALE - refresh",IF($S24>=5,"A - go now",IF($S24>=3,"B - worth it","C - later"))))) -> B - worth it | W24: 514-684-6270 | X24: communication@hfs.qc.ca | Y24: Email | AA24: https://www.hfs.qc.ca/ | AB24: 46281 | AH24: =IF(OR($AF24="",$AG24=""),"",$AG24-$AF24) | AM24: =IF($AG24="","",$AG24+30) | AT24: 2 rue Hope, DDO H9A 2V5. Bilingual, preschool to grade 6 plus a separate high school division - two buildings. Published general email. Note: preschool division on site means the disinfection-outside-children's-presence angle applies here too.
A25: West Island College | B25: School | C25: Dollard-des-Ormeaux | D25: EN | F25: Private | O25: Pre-winter floors | P25: 46327 | Q25: Yes | R25: One-off - Strip & wax | S25: =IF($A25="","",IF(LEFT($B25,2)="DQ",0,(IF($Q25="Yes",1,0)+IF(AND($O25<>"",$O25<>"None known",OR($P25="",$P25>=TODAY())),1,0)+IF(AND($B25<>"",LEFT($B25,2)<>"DQ"),1,0)+IF(AND($C25<>"",$C25<>"Outside corridor"),1,0)+IF(AND($W25<>"",$U25<>""),1,0)+IF(AND(ISNUMBER($E25),$E25>=3000,$E25<=15000),1,0)))) -> 4 | T25: =IF($A25="","",IF(LEFT($B25,2)="DQ","DQ - do not work",IF(AND($P25<>"",$P25<TODAY()),"STALE - refresh",IF($S25>=5,"A - go now",IF($S25>=3,"B - worth it","C - later"))))) -> B - worth it | W25: 514-683-4660 | Y25: Call | AA25: https://wicmtl.ca/ | AB25: 46281 | AH25: =IF(OR($AF25="",$AG25=""),"",$AG25-$AF25) | AM25: =IF($AG25="","",$AG25+30) | AT25: CALL ONLY - site obfuscates its email address, so no CASL basis. 851 Tecumseh, DDO H9B 2L2. Independent school, FEEP member. Ask for the business manager or director general.
A26: Emmanuel Christian School | B26: School | C26: Dollard-des-Ormeaux | D26: EN | F26: Private | O26: Pre-winter floors | P26: 46327 | Q26: Yes | R26: One-off - Strip & wax | S26: =IF($A26="","",IF(LEFT($B26,2)="DQ",0,(IF($Q26="Yes",1,0)+IF(AND($O26<>"",$O26<>"None known",OR($P26="",$P26>=TODAY())),1,0)+IF(AND($B26<>"",LEFT($B26,2)<>"DQ"),1,0)+IF(AND($C26<>"",$C26<>"Outside corridor"),1,0)+IF(AND($W26<>"",$U26<>""),1,0)+IF(AND(ISNUMBER($E26),$E26>=3000,$E26<=15000),1,0)))) -> 4 | T26: =IF($A26="","",IF(LEFT($B26,2)="DQ","DQ - do not work",IF(AND($P26<>"",$P26<TODAY()),"STALE - refresh",IF($S26>=5,"A - go now",IF($S26>=3,"B - worth it","C - later"))))) -> B - worth it | W26: 514-696-6430 | Y26: Call | AA26: https://ville.ddo.qc.ca/en/live/community-and-institutions/educational-institutions/ | AB26: 46281 | AH26: =IF(OR($AF26="",$AG26=""),"",$AG26-$AF26) | AM26: =IF($AG26="","",$AG26+30) | AT26: CALL ONLY - site blocked to automated fetch, no published email verified. 4698 rue St-Jean, DDO. Listed on the City of DDO educational institutions page.
A27: Montreal Confucius School | B27: School | C27: Dollard-des-Ormeaux | D27: EN | F27: Private | O27: Pre-winter floors | P27: 46327 | Q27: Yes | R27: One-off - Deep clean | S27: =IF($A27="","",IF(LEFT($B27,2)="DQ",0,(IF($Q27="Yes",1,0)+IF(AND($O27<>"",$O27<>"None known",OR($P27="",$P27>=TODAY())),1,0)+IF(AND($B27<>"",LEFT($B27,2)<>"DQ"),1,0)+IF(AND($C27<>"",$C27<>"Outside corridor"),1,0)+IF(AND($W27<>"",$U27<>""),1,0)+IF(AND(ISNUMBER($E27),$E27>=3000,$E27<=15000),1,0)))) -> 4 | T27: =IF($A27="","",IF(LEFT($B27,2)="DQ","DQ - do not work",IF(AND($P27<>"",$P27<TODAY()),"STALE - refresh",IF($S27>=5,"A - go now",IF($S27>=3,"B - worth it","C - later"))))) -> B - worth it | W27: 514-691-0412 | Y27: Call | AA27: https://ville.ddo.qc.ca/en/live/community-and-institutions/educational-institutions/ | AB27: 46281 | AH27: =IF(OR($AF27="",$AG27=""),"",$AG27-$AF27) | AM27: =IF($AG27="","",$AG27+30) | AT27: CALL ONLY - no published email verified. 851 Tecumseh, DDO - shares an address with West Island College, so likely a tenant in that building. Ask who cleans before pitching: this may be the landlord's decision. Weekend/supplementary school, so lower volume.
A28: St. George's School of Montreal | B28: School | C28: Westmount | D28: EN | F28: Private | O28: Pre-winter floors | P28: 46327 | Q28: Yes | R28: One-off - Strip & wax | S28: =IF($A28="","",IF(LEFT($B28,2)="DQ",0,(IF($Q28="Yes",1,0)+IF(AND($O28<>"",$O28<>"None known",OR($P28="",$P28>=TODAY())),1,0)+IF(AND($B28<>"",LEFT($B28,2)<>"DQ"),1,0)+IF(AND($C28<>"",$C28<>"Outside corridor"),1,0)+IF(AND($W28<>"",$U28<>""),1,0)+IF(AND(ISNUMBER($E28),$E28>=3000,$E28<=15000),1,0)))) -> 4 | T28: =IF($A28="","",IF(LEFT($B28,2)="DQ","DQ - do not work",IF(AND($P28<>"",$P28<TODAY()),"STALE - refresh",IF($S28>=5,"A - go now",IF($S28>=3,"B - worth it","C - later"))))) -> B - worth it | W28: 514-937-9289 | Y28: Call | AA28: https://www.stgeorges.qc.ca/ | AB28: 46281 | AH28: =IF(OR($AF28="",$AG28=""),"",$AG28-$AF28) | AM28: =IF($AG28="","",$AG28+30) | AT28: CALL ONLY on purpose. Two Westmount campuses - 3685 The Boulevard and 3100 Le Boulevard - K to 12, founded 1930. Only admissions@stgeorges.qc.ca is published, which is not the facilities buyer, so there is no role-relevant CASL basis. Phone and ask for the business manager.
A29: English Montreal School Board / Lester B. Pearson School Board | B29: School | C29: Other - in corridor | D29: EN | F29: Public | O29: Contract expiring | Q29: Yes | R29: Recurring contract | S29: =IF($A29="","",IF(LEFT($B29,2)="DQ",0,(IF($Q29="Yes",1,0)+IF(AND($O29<>"",$O29<>"None known",OR($P29="",$P29>=TODAY())),1,0)+IF(AND($B29<>"",LEFT($B29,2)<>"DQ"),1,0)+IF(AND($C29<>"",$C29<>"Outside corridor"),1,0)+IF(AND($W29<>"",$U29<>""),1,0)+IF(AND(ISNUMBER($E29),$E29>=3000,$E29<=15000),1,0)))) -> 4 | T29: =IF($A29="","",IF(LEFT($B29,2)="DQ","DQ - do not work",IF(AND($P29<>"",$P29<TODAY()),"STALE - refresh",IF($S29>=5,"A - go now",IF($S29>=3,"B - worth it","C - later"))))) -> B - worth it | Y29: Property manager | AA29: https://ville.ddo.qc.ca/en/live/community-and-institutions/educational-institutions/ | AB29: 46281 | AH29: =IF(OR($AF29="",$AG29=""),"",$AG29-$AF29) | AM29: =IF($AG29="","",$AG29+30) | AT29: DO NOT COLD-APPROACH. Both are public bodies - their cleaning is tendered through SEAO, so a call to a principal goes nowhere. LBPSB 514-422-3000. This row exists as a standing watch item: the SEAO feed is the route, on the contract-expiry trigger. Loaded as a reminder, not a lead - set Status accordingly.
A30: Beaurepaire Preschool | B30: Kindergarten / preschool | C30: Beaconsfield | D30: EN | F30: Private | O30: Pre-winter floors | P30: 46327 | Q30: Yes | R30: One-off - Deep clean | S30: =IF($A30="","",IF(LEFT($B30,2)="DQ",0,(IF($Q30="Yes",1,0)+IF(AND($O30<>"",$O30<>"None known",OR($P30="",$P30>=TODAY())),1,0)+IF(AND($B30<>"",LEFT($B30,2)<>"DQ"),1,0)+IF(AND($C30<>"",$C30<>"Outside corridor"),1,0)+IF(AND($W30<>"",$U30<>""),1,0)+IF(AND(ISNUMBER($E30),$E30>=3000,$E30<=15000),1,0)))) -> 4 | T30: =IF($A30="","",IF(LEFT($B30,2)="DQ","DQ - do not work",IF(AND($P30<>"",$P30<TODAY()),"STALE - refresh",IF($S30>=5,"A - go now",IF($S30>=3,"B - worth it","C - later"))))) -> B - worth it | V30: Registrar | W30: 514-695-4609 | X30: registrar@beaurepairepreschool.com | Y30: Email | AA30: https://westislandmommies.com/directory/preschools-2/ | AB30: 46281 | AH30: =IF(OR($AF30="",$AG30=""),"",$AG30-$AF30) | AM30: =IF($AG30="","",$AG30+30) | AT30: 25 Fieldfare, Beaconsfield. Published email. Likely a co-op or small independent - decision may sit with a volunteer parent board, so expect a slower yes. Verify who owns the building before scoring as live.
A31: Magic Circle Preschool | B31: Kindergarten / preschool | C31: Beaconsfield | D31: EN | F31: Private | O31: Pre-winter floors | P31: 46327 | Q31: Yes | R31: One-off - Deep clean | S31: =IF($A31="","",IF(LEFT($B31,2)="DQ",0,(IF($Q31="Yes",1,0)+IF(AND($O31<>"",$O31<>"None known",OR($P31="",$P31>=TODAY())),1,0)+IF(AND($B31<>"",LEFT($B31,2)<>"DQ"),1,0)+IF(AND($C31<>"",$C31<>"Outside corridor"),1,0)+IF(AND($W31<>"",$U31<>""),1,0)+IF(AND(ISNUMBER($E31),$E31>=3000,$E31<=15000),1,0)))) -> 4 | T31: =IF($A31="","",IF(LEFT($B31,2)="DQ","DQ - do not work",IF(AND($P31<>"",$P31<TODAY()),"STALE - refresh",IF($S31>=5,"A - go now",IF($S31>=3,"B - worth it","C - later"))))) -> B - worth it | W31: 514-608-9956 | X31: info@magiccirclepreschool.com | Y31: Email | AA31: https://westislandmommies.com/directory/preschools-2/ | AB31: 46281 | AH31: =IF(OR($AF31="",$AG31=""),"",$AG31-$AF31) | AM31: =IF($AG31="","",$AG31+30) | AT31: 313 Windermere Road, Beaconsfield H9W 1W1. Published email and own website. Appears to be a standalone operator rather than a co-op, which makes the decision faster.
A32: Montessori School of Pointe-Claire | B32: Kindergarten / preschool | C32: Pointe-Claire | D32: EN | F32: Private | O32: Pre-winter floors | P32: 46327 | Q32: Yes | R32: One-off - Deep clean | S32: =IF($A32="","",IF(LEFT($B32,2)="DQ",0,(IF($Q32="Yes",1,0)+IF(AND($O32<>"",$O32<>"None known",OR($P32="",$P32>=TODAY())),1,0)+IF(AND($B32<>"",LEFT($B32,2)<>"DQ"),1,0)+IF(AND($C32<>"",$C32<>"Outside corridor"),1,0)+IF(AND($W32<>"",$U32<>""),1,0)+IF(AND(ISNUMBER($E32),$E32>=3000,$E32<=15000),1,0)))) -> 4 | T32: =IF($A32="","",IF(LEFT($B32,2)="DQ","DQ - do not work",IF(AND($P32<>"",$P32<TODAY()),"STALE - refresh",IF($S32>=5,"A - go now",IF($S32>=3,"B - worth it","C - later"))))) -> B - worth it | W32: 514-697-3792 | X32: montessori.school.pc@gmail.com | Y32: Email | AA32: https://westislandmommies.com/directory/preschools-2/ | AB32: 46281 | AH32: =IF(OR($AF32="",$AG32=""),"",$AG32-$AF32) | AM32: =IF($AG32="","",$AG32+30) | AT32: 116 Sunderland Ave, Pointe-Claire. Published email. Montessori settings use extensive floor-level materials and hard floors, which makes the disinfection-outside-children's-presence angle unusually strong here.
A33: Coolbrooke Park Preschool | B33: Kindergarten / preschool | C33: Dollard-des-Ormeaux | D33: EN | F33: Private | O33: Pre-winter floors | P33: 46327 | Q33: Yes | R33: One-off - Deep clean | S33: =IF($A33="","",IF(LEFT($B33,2)="DQ",0,(IF($Q33="Yes",1,0)+IF(AND($O33<>"",$O33<>"None known",OR($P33="",$P33>=TODAY())),1,0)+IF(AND($B33<>"",LEFT($B33,2)<>"DQ"),1,0)+IF(AND($C33<>"",$C33<>"Outside corridor"),1,0)+IF(AND($W33<>"",$U33<>""),1,0)+IF(AND(ISNUMBER($E33),$E33>=3000,$E33<=15000),1,0)))) -> 4 | T33: =IF($A33="","",IF(LEFT($B33,2)="DQ","DQ - do not work",IF(AND($P33<>"",$P33<TODAY()),"STALE - refresh",IF($S33>=5,"A - go now",IF($S33>=3,"B - worth it","C - later"))))) -> B - worth it | W33: 438-936-7671 | X33: coolbrookepreschool@gmail.com | Y33: Email | AA33: https://ville.ddo.qc.ca/en/live/community-and-institutions/educational-institutions/ | AB33: 46281 | AH33: =IF(OR($AF33="",$AG33=""),"",$AG33-$AF33) | AM33: =IF($AG33="","",$AG33+30) | AT33: 260 Spring Garden, DDO. Published on the City of DDO page. Small site - check whether the premises are municipally owned before treating it as a live prospect.
A34: Westpark Cooperative Preschool | B34: Kindergarten / preschool | C34: Dollard-des-Ormeaux | D34: EN | F34: Private | G34: City of Dollard-des-Ormeaux (probable) | O34: Pre-winter floors | P34: 46327 | Q34: Yes | R34: Backup list | S34: =IF($A34="","",IF(LEFT($B34,2)="DQ",0,(IF($Q34="Yes",1,0)+IF(AND($O34<>"",$O34<>"None known",OR($P34="",$P34>=TODAY())),1,0)+IF(AND($B34<>"",LEFT($B34,2)<>"DQ"),1,0)+IF(AND($C34<>"",$C34<>"Outside corridor"),1,0)+IF(AND($W34<>"",$U34<>""),1,0)+IF(AND(ISNUMBER($E34),$E34>=3000,$E34<=15000),1,0)))) -> 4 | T34: =IF($A34="","",IF(LEFT($B34,2)="DQ","DQ - do not work",IF(AND($P34<>"",$P34<TODAY()),"STALE - refresh",IF($S34>=5,"A - go now",IF($S34>=3,"B - worth it","C - later"))))) -> B - worth it | W34: 514-400-8133 | X34: westparkpreschool@hotmail.com | Y34: Email | AA34: https://westislandmommies.com/directory/preschools-2/ | AB34: 46281 | AH34: =IF(OR($AF34="",$AG34=""),"",$AG34-$AF34) | AM34: =IF($AG34="","",$AG34+30) | AT34: Operates from the Terry Fox park chalet, 100 Fairview, DDO (also listed at 85 Hemingway). BUILDING IS PROBABLY CITY-OWNED - the municipality may already clean it, so confirm before pitching a contract. Backup list is the right first ask here. Parent co-op, volunteer board.
A35: Dorval Preschool Co-op | B35: Kindergarten / preschool | C35: Dorval | D35: EN | F35: Private | G35: City of Dorval (probable) | O35: Pre-winter floors | P35: 46327 | Q35: Yes | R35: Backup list | S35: =IF($A35="","",IF(LEFT($B35,2)="DQ",0,(IF($Q35="Yes",1,0)+IF(AND($O35<>"",$O35<>"None known",OR($P35="",$P35>=TODAY())),1,0)+IF(AND($B35<>"",LEFT($B35,2)<>"DQ"),1,0)+IF(AND($C35<>"",$C35<>"Outside corridor"),1,0)+IF(AND($W35<>"",$U35<>""),1,0)+IF(AND(ISNUMBER($E35),$E35>=3000,$E35<=15000),1,0)))) -> 4 | T35: =IF($A35="","",IF(LEFT($B35,2)="DQ","DQ - do not work",IF(AND($P35<>"",$P35<TODAY()),"STALE - refresh",IF($S35>=5,"A - go now",IF($S35>=3,"B - worth it","C - later"))))) -> B - worth it | W35: 514-633-4000 | X35: DorvalPreschoolCoopSDCC@gmail.com | Y35: Email | AA35: https://westislandmommies.com/directory/preschools-2/ | AB35: 46281 | AH35: =IF(OR($AF35="",$AG35=""),"",$AG35-$AF35) | AM35: =IF($AG35="","",$AG35+30) | AT35: Inside the Sarto Desnoyers Community Centre, 1335 Lakeshore Drive, Dorval. BUILDING IS MUNICIPAL - City of Dorval very likely cleans it. Worth a call to confirm; if the City does clean it, the real lead is the City's facilities team, not the co-op.
A36: Prematernelle Parksites Preschool | B36: Kindergarten / preschool | C36: Pointe-Claire | D36: EN | F36: Private | G36: St. Columba Church (probable) | O36: Pre-winter floors | P36: 46327 | Q36: Yes | R36: Backup list | S36: =IF($A36="","",IF(LEFT($B36,2)="DQ",0,(IF($Q36="Yes",1,0)+IF(AND($O36<>"",$O36<>"None known",OR($P36="",$P36>=TODAY())),1,0)+IF(AND($B36<>"",LEFT($B36,2)<>"DQ"),1,0)+IF(AND($C36<>"",$C36<>"Outside corridor"),1,0)+IF(AND($W36<>"",$U36<>""),1,0)+IF(AND(ISNUMBER($E36),$E36>=3000,$E36<=15000),1,0)))) -> 4 | T36: =IF($A36="","",IF(LEFT($B36,2)="DQ","DQ - do not work",IF(AND($P36<>"",$P36<TODAY()),"STALE - refresh",IF($S36>=5,"A - go now",IF($S36>=3,"B - worth it","C - later"))))) -> B - worth it | W36: 438-989-7908 | X36: info@parksites.ca | Y36: Email | AA36: https://westislandmommies.com/directory/preschools-2/ | AB36: 46281 | AH36: =IF(OR($AF36="",$AG36=""),"",$AG36-$AF36) | AM36: =IF($AG36="","",$AG36+30) | AT36: Operates from St. Columba Church, 11 Rodney Ave, Pointe-Claire. CHURCH-OWNED BUILDING - the parish may already clean it. If so the church itself is the better lead. Confirm on the call.
A37: Garderie educative Ange gardien | B37: Daycare / CPE | C37: Dollard-des-Ormeaux | D37: EN | F37: Private | O37: Pre-winter floors | P37: 46327 | Q37: Yes | R37: One-off - Deep clean | S37: =IF($A37="","",IF(LEFT($B37,2)="DQ",0,(IF($Q37="Yes",1,0)+IF(AND($O37<>"",$O37<>"None known",OR($P37="",$P37>=TODAY())),1,0)+IF(AND($B37<>"",LEFT($B37,2)<>"DQ"),1,0)+IF(AND($C37<>"",$C37<>"Outside corridor"),1,0)+IF(AND($W37<>"",$U37<>""),1,0)+IF(AND(ISNUMBER($E37),$E37>=3000,$E37<=15000),1,0)))) -> 4 | T37: =IF($A37="","",IF(LEFT($B37,2)="DQ","DQ - do not work",IF(AND($P37<>"",$P37<TODAY()),"STALE - refresh",IF($S37>=5,"A - go now",IF($S37>=3,"B - worth it","C - later"))))) -> B - worth it | W37: 514-685-2032 | Y37: Call | AA37: https://ville.ddo.qc.ca/en/live/community-and-institutions/educational-institutions/ | AB37: 46281 | AH37: =IF(OR($AF37="",$AG37=""),"",$AG37-$AF37) | AM37: =IF($AG37="","",$AG37+30) | AT37: CALL ONLY - no published email. 3869 Sources Blvd #100, DDO. Private garderie rather than a subsidised CPE, so it buys its own services directly - better odds than a CPE.
A38: Or-Maimonide Day Care | B38: Daycare / CPE | C38: Dollard-des-Ormeaux | D38: EN | F38: Private | O38: Pre-winter floors | P38: 46327 | Q38: Yes | R38: One-off - Deep clean | S38: =IF($A38="","",IF(LEFT($B38,2)="DQ",0,(IF($Q38="Yes",1,0)+IF(AND($O38<>"",$O38<>"None known",OR($P38="",$P38>=TODAY())),1,0)+IF(AND($B38<>"",LEFT($B38,2)<>"DQ"),1,0)+IF(AND($C38<>"",$C38<>"Outside corridor"),1,0)+IF(AND($W38<>"",$U38<>""),1,0)+IF(AND(ISNUMBER($E38),$E38>=3000,$E38<=15000),1,0)))) -> 4 | T38: =IF($A38="","",IF(LEFT($B38,2)="DQ","DQ - do not work",IF(AND($P38<>"",$P38<TODAY()),"STALE - refresh",IF($S38>=5,"A - go now",IF($S38>=3,"B - worth it","C - later"))))) -> B - worth it | W38: 514-676-1531 | Y38: Call | AA38: https://ville.ddo.qc.ca/en/live/community-and-institutions/educational-institutions/ | AB38: 46281 | AH38: =IF(OR($AF38="",$AG38=""),"",$AG38-$AF38) | AM38: =IF($AG38="","",$AG38+30) | AT38: CALL ONLY - no published email. 96 Fredmir, DDO. Likely linked to the Or-Maimonide school network, which could open a larger relationship.
A39: CPE Les Bois Verts | B39: Daycare / CPE | C39: Dollard-des-Ormeaux | D39: FR | F39: Public | O39: Pre-winter floors | P39: 46327 | Q39: Yes | R39: Backup list | S39: =IF($A39="","",IF(LEFT($B39,2)="DQ",0,(IF($Q39="Yes",1,0)+IF(AND($O39<>"",$O39<>"None known",OR($P39="",$P39>=TODAY())),1,0)+IF(AND($B39<>"",LEFT($B39,2)<>"DQ"),1,0)+IF(AND($C39<>"",$C39<>"Outside corridor"),1,0)+IF(AND($W39<>"",$U39<>""),1,0)+IF(AND(ISNUMBER($E39),$E39>=3000,$E39<=15000),1,0)))) -> 4 | T39: =IF($A39="","",IF(LEFT($B39,2)="DQ","DQ - do not work",IF(AND($P39<>"",$P39<TODAY()),"STALE - refresh",IF($S39>=5,"A - go now",IF($S39>=3,"B - worth it","C - later"))))) -> B - worth it | W39: 514-684-7712 | Y39: Call | AA39: https://ville.ddo.qc.ca/en/live/community-and-institutions/educational-institutions/ | AB39: 46281 | AH39: =IF(OR($AF39="",$AG39=""),"",$AG39-$AF39) | AM39: =IF($AG39="","",$AG39+30) | AT39: CALL ONLY - no published email. 50 Seville, DDO. Subsidised CPE, so purchasing may run through a group arrangement - unverified. French-named operator, outside the anglophone rule strictly speaking; loaded for completeness of the DDO sweep, deprioritise.
A40: CPE Dollard | B40: Daycare / CPE | C40: Dollard-des-Ormeaux | D40: FR | F40: Public | O40: Pre-winter floors | P40: 46327 | Q40: Yes | R40: Backup list | S40: =IF($A40="","",IF(LEFT($B40,2)="DQ",0,(IF($Q40="Yes",1,0)+IF(AND($O40<>"",$O40<>"None known",OR($P40="",$P40>=TODAY())),1,0)+IF(AND($B40<>"",LEFT($B40,2)<>"DQ"),1,0)+IF(AND($C40<>"",$C40<>"Outside corridor"),1,0)+IF(AND($W40<>"",$U40<>""),1,0)+IF(AND(ISNUMBER($E40),$E40>=3000,$E40<=15000),1,0)))) -> 4 | T40: =IF($A40="","",IF(LEFT($B40,2)="DQ","DQ - do not work",IF(AND($P40<>"",$P40<TODAY()),"STALE - refresh",IF($S40>=5,"A - go now",IF($S40>=3,"B - worth it","C - later"))))) -> B - worth it | W40: 514-683-7366 | Y40: Call | AA40: https://ville.ddo.qc.ca/en/live/community-and-institutions/educational-institutions/ | AB40: 46281 | AH40: =IF(OR($AF40="",$AG40=""),"",$AG40-$AF40) | AM40: =IF($AG40="","",$AG40+30) | AT40: CALL ONLY - no published email. 2000 De Salaberry Blvd, DDO. Subsidised CPE, same caveat as Les Bois Verts. Deprioritise under the anglophone rule.
...

Sheet Pipeline
A1: PIPELINE
A2: Everything here reads from the Leads tab. Do not type in column B.
A4: THE DESTINATION
A5: LONG-TERM CONTRACTS WON | B5: =COUNTIF(Leads!$AR$4:$AR$100,"CONTRACT WON") -> 0 | C5: The actual goal. Everything else is a route to this.
A6: Recurring value won ($/month) | B6: =SUMIF(Leads!$AR$4:$AR$100,"CONTRACT WON",Leads!$AS$4:$AS$100) -> 0
A7: Capacity remaining | B7: =5-COUNTIF(Leads!$AR$4:$AR$100,"CONTRACT WON") -> 5 | C7: Ceiling is 3-5 medium contracts. Do not oversell.
A9: ROUTES IN
A10: New clients won (total) | B10: =COUNTIF(Leads!$AD$4:$AD$100,"Won - one-off job")+COUNTIF(Leads!$AD$4:$AD$100,"Won - CONTRACT") -> 0 | C10: The GTS scorecard
A11: of which one-off jobs | B11: =COUNTIF(Leads!$AD$4:$AD$100,"Won - one-off job") -> 0 | C11: Route 1 — the way in
A12: of which straight to contract | B12: =COUNTIF(Leads!$AD$4:$AD$100,"Won - CONTRACT") -> 0
A13: On the backup list | B13: =COUNTIF(Leads!$AQ$4:$AQ$100,"Yes") -> 0 | C13: Route 2 — the easiest yes there is
A15: CONTRACT CONVERSION
A16: Contract raised in conversation | B16: =COUNTIF(Leads!$AR$4:$AR$100,"Raised in conversation") -> 0
A17: Contract proposals sent | B17: =COUNTIF(Leads!$AR$4:$AR$100,"Contract proposal sent") -> 0
A18: Won jobs NOT yet raised | B18: =COUNTIFS(Leads!$AD$4:$AD$100,"Won - one-off job",Leads!$AR$4:$AR$100,"Not yet raised") -> 0 | C18: ⚠️ Every one of these is a missed contract. Chase them.
A19: One-off → contract rate | B19: =IF(COUNTIF(Leads!$AD$4:$AD$100,"Won - one-off job")=0,"—",TEXT(COUNTIF(Leads!$AR$4:$AR$100,"CONTRACT WON")/COUNTIF(Leads!$AD$4:$AD$100,"Won - one-off job"),"0%")) -> — | C19: The number that proves the whole strategy
A21: PIPELINE
A22: Total leads | B22: =COUNTA(Leads!$A$4:$A$100)-COUNTIF(Leads!$A$4:$A$100,"EXAMPLE*") -> 37
A23: A — go now | B23: =COUNTIF(Leads!$T$4:$T$100,"A - go now") -> 5 | C23: Work these first
A24: B — worth it | B24: =COUNTIF(Leads!$T$4:$T$100,"B - worth it") -> 32
A25: C — later | B25: =COUNTIF(Leads!$T$4:$T$100,"C - later") -> 0
A26: STALE — trigger expired | B26: =COUNTIF(Leads!$T$4:$T$100,"STALE - refresh") -> 0 | C26: ⚠️ Re-run the sourcing skill on these
A27: Disqualified | B27: =COUNTIF(Leads!$T$4:$T$100,"DQ*") -> 0 | C27: Wrong sector. Do not work these
A28: A-leads not yet approached | B28: =COUNTIFS(Leads!$T$4:$T$100,"A - go now",Leads!$AD$4:$AD$100,"Not started") -> 3 | C28: ⚠️ If this is high, nothing else matters
A30: ACTIVITY
A31: Contacted | B31: =COUNTIF(Leads!$AD$4:$AD$100,"Contacted") -> 0
A32: Walkthroughs done | B32: =COUNT(Leads!$AF$4:$AF$100) -> 0
A33: Proposals sent | B33: =COUNT(Leads!$AG$4:$AG$100) -> 0
A34: Referrals received | B34: =COUNTA(Leads!$Z$4:$Z$100) -> 0
A35: Walkthrough → proposal | B35: =IF(COUNT(Leads!$AF$4:$AF$100)=0,"—",TEXT(COUNT(Leads!$AG$4:$AG$100)/COUNT(Leads!$AF$4:$AF$100),"0%")) -> —
A36: Avg days walkthrough → proposal | B36: =IF(COUNT(Leads!$AH$4:$AH$100)=0,"—",ROUND(AVERAGE(Leads!$AH$4:$AH$100),1)) -> — | C36: ⚠️ Slow proposals lose deals. Keep this low
A38: MONEY
A39: Total quoted | B39: =SUM(Leads!$AI$4:$AI$100) -> 0
A40: Value of won jobs | B40: =SUMIF(Leads!$AD$4:$AD$100,"Won - one-off job",Leads!$AI$4:$AI$100)+SUMIF(Leads!$AD$4:$AD$100,"Won - CONTRACT",Leads!$AI$4:$AI$100) -> 0
A41: Total paid in | B41: =SUM(Leads!$AP$4:$AP$100) -> 0 | C41: Actual cash, not promises
A42: Outstanding | B42: =SUMIF(Leads!$AD$4:$AD$100,"Won - one-off job",Leads!$AI$4:$AI$100)+SUMIF(Leads!$AD$4:$AD$100,"Won - CONTRACT",Leads!$AI$4:$AI$100)-SUM(Leads!$AP$4:$AP$100) -> 0
